Traceback (most recent call last):
  File "D:\MCTS-AHD-master\problems\tsp_constructive\eval.py", line 11, in <module>
    from gpt import select_next_node_v2 as select_next_node
  File "D:\MCTS-AHD-master\problems\tsp_constructive\gpt.py", line 2
    next_node = random.choices([s[0] for s in scores], weights=[1/s[1] for s in scores], k=1)[0]
IndentationError: unexpected indent

During handling of the above exception, another exception occurred:

Traceback (most recent call last):
  File "D:\MCTS-AHD-master\problems\tsp_constructive\eval.py", line 13, in <module>
    from gpt import select_next_node
  File "D:\MCTS-AHD-master\problems\tsp_constructive\gpt.py", line 2
    next_node = random.choices([s[0] for s in scores], weights=[1/s[1] for s in scores], k=1)[0]
IndentationError: unexpected indent
